Workbook
Name Child_Goal: '9'!$T$104:$T$109
Name HOME: #REF!
Name HOME2: #REF!
Name MF_TYPES: '[1]6'!$Q$5:$Q$7
Name MF_TYPES: '[1]6'!$Q$5:$Q$7
Name MF_TYPES: '3'!$S$5:$S$7
Name TaxSlab: '[1]6'!$P$5:$P$11
Name TaxSlab: '[1]6'!$P$5:$P$11
Name TaxSlab: '3'!$R$1:$R$7

Sheet Main Menu
A4: PERSONAL FINANCE CALCULATORS
A8: SIP & Lump Sum All in One | E8: Find out required amount of investment or wealth to be created for variety of scenarios | J8: What amount of investment you need to make to safeguard your retirement years | O8: Retirement Calculator
A12: SWP Calculator | E12: Check how Systematic Withdrawal Plan performs during distribution phase | J12: What if you increase the loan tenure and start SIP of the difference amt | O12: Home Loan Tenure & SIP Calculator
A16: SWP vs FD Interest | E16: How SWP is tax effective compared to Fixed Deposit interest payout - find out here | J16: Take care of your health cover, life cover and wealth creation in simplest manner | O16: 3 - in - 1 Calculator
A20: SIP + SWP | E20: Detailed analysis of wealth creation (SIP) & distribution (SWP) process | J20: Create multiple financial goals, plan retirement, cover health, life - all in one | O20: Quick Financial Plan
A24: Term Insurance Planning | E24: Get to know how much life cover you require based on expense replacement | J24: Find out wealth creation, reqd. investment, return, tenure - for SIP and lump sum | O24: Quick Calcys
A29: Prepared for: | C29: Client Name | J29: Prepared by: | L29: Partner Name
A30: Disclaimer: Result or output of these calculators are for representational purpose only. Assumptions made here, may or may not be appropriate considering your needs, priorities and risk profile. Check with an expert before taking any financial decision.

Sheet 1 (1)
V1: ="FV of SIP wealth after "&G14&" years" -> FV of SIP wealth after 20 years | Y1: =IF(G14+G15>50,0,VLOOKUP(G14,$V$9:$X$58,3,0)) -> 25507446
A2: BACK | B2: SIP & LUMP SUM - ALL IN ONE | V2: ="FV of SIP wealth after "&G14+G15&" years" -> FV of SIP wealth after 30 years | Y2: =FV($G$16,G15,,-Y1) -> 79222255
V3: ="FV of lump sum wealth after "&$G$14+$G$15&" years" -> FV of lump sum wealth after 30 years | Y3: =FV(G18,G14+G15,,-G17) -> 5991984.4
V4: ="FV of fixed SIP wealth after "&G14&" years" -> FV of fixed SIP wealth after 20 years | Y4: =FV((1+$G$16)^(1/12)-1,$G$14*12,-G9,,1) -> 18397147
D5: Future Wealth Creation | J5: Required Investment to Make
B7: How much wealth can be created? | V7: =IF(M17>M7,"SIP tenure cannot be more than goal tenure","") -> SIP tenure cannot be more than goal tenure
V8: YEARS | W8: SIP | X8: WEALTH | Y8: SIP INV AMT
B9: SIP amount (per month) | G9: 20000 | J9: YEAR | K9: MTHLY SIP AMT | M9: WEALTH @ END OF YEAR | V9: 1 | W9: =G9 -> 20000 | X9: =FV((1+$G$16)^(1/12)-1,12,-W9,,1) -> 255329.96 | Y9: =W9*12 -> 240000
B10: SIP top-up % (after every 12 months) | G10: 0.05 | J10: 1 | K10: =G9 -> 20000 | M10: =FV((1+$G$16)^(1/12)-1,12,-K10,IF(ISNUMBER(M9),-M9,0),1) -> 255329.96 | Q10: =J10<=$G$14 -> TRUE | R10: =J10="" -> FALSE | S10: =IF(R10=FALSE,IF(MOD(ROW(),2)=0,"WHITE","ORANGE")) -> WHITE | T10: =K10*12 -> 240000 | U10: =T10 -> 240000 | V10: 2 | W10: =IF(V10>$G$14,0, W9*(1+$G$10)) -> 21000 | X10: =IF(W10=0,0,FV((1+$G$16)^(1/12)-1,12,-W10,-X9,1)) -> 554066.01 | Y10: =W10*12 -> 252000
B11: SIP top-up amount (after every 12 months) | J11: =IF(J10="","",IF(J10+1>$G$14 + $G$15,"",J10+1)) -> 2 | K11: =IF(J11="","",IF(Q11, IF($G$13="Percentage", IF(OR(ISBLANK($G$12),$G$12=0),K10*(1+$G$10),IF(K10*(1+$G$10)>$G$12,K10,K10*(1+$G$10))), IF(OR(ISBLANK($G$12),$G$12=0),K10+$G$11, IF(K10+$G$11>$G$12,K10, K10+$G$11))), 0)) -> 21000 | M11: =IF(J11="","",FV((1+$G$16)^(1/12)-1,12,-K11,IF(ISNUMBER(M10),-M10,0),1)) -> 554066.01 | Q11: =J11<=$G$14 -> TRUE | R11: =J11="" -> FALSE | S11: =IF(R11=FALSE,IF(MOD(ROW(),2)=0,"WHITE","ORANGE")) -> ORANGE | T11: =K11*12 -> 252000 | U11: =U10+T11 -> 492000 | V11: 3 | W11: =IF(V11>$G$14,0, W10*(1+$G$10)) -> 22050 | X11: =IF(W11=0,0,FV((1+$G$16)^(1/12)-1,12,-W11,-X10,1)) -> 902055.21 | Y11: =W11*12 -> 264600
B12: Max SIP amount cap (for both - % or amount top-up) | J12: =IF(J11="","",IF(J11+1>$G$14 + $G$15,"",J11+1)) -> 3 | K12: =IF(J12="","",IF(Q12, IF($G$13="Percentage", IF(OR(ISBLANK($G$12),$G$12=0),K11*(1+$G$10),IF(K11*(1+$G$10)>$G$12,K11,K11*(1+$G$10))), IF(OR(ISBLANK($G$12),$G$12=0),K11+$G$11, IF(K11+$G$11>$G$12,K11, K11+$G$11))), 0)) -> 22050 | M12: =IF(J12="","",FV((1+$G$16)^(1/12)-1,12,-K12,IF(ISNUMBER(M11),-M11,0),1)) -> 902055.21 | Q12: =J12<=$G$14 -> TRUE | R12: =J12="" -> FALSE | S12: =IF(R12=FALSE,IF(MOD(ROW(),2)=0,"WHITE","ORANGE")) -> WHITE | T12: =K12*12 -> 264600 | U12: =U11+T12 -> 756600 | V12: 4 | W12: =IF(V12>$G$14,0, W11*(1+$G$10)) -> 23152.5 | X12: =IF(W12=0,0,FV((1+$G$16)^(1/12)-1,12,-W12,-X11,1)) -> 1305878.2 | Y12: =W12*12 -> 277830
B13: Here future value calculation is to be based on | G13: Percentage | J13: =IF(J12="","",IF(J12+1>$G$14 + $G$15,"",J12+1)) -> 4 | K13: =IF(J13="","",IF(Q13, IF($G$13="Percentage", IF(OR(ISBLANK($G$12),$G$12=0),K12*(1+$G$10),IF(K12*(1+$G$10)>$G$12,K12,K12*(1+$G$10))), IF(OR(ISBLANK($G$12),$G$12=0),K12+$G$11, IF(K12+$G$11>$G$12,K12, K12+$G$11))), 0)) -> 23152.5 | M13: =IF(J13="","",FV((1+$G$16)^(1/12)-1,12,-K13,IF(ISNUMBER(M12),-M12,0),1)) -> 1305878.2 | Q13: =J13<=$G$14 -> TRUE | R13: =J13="" -> FALSE | S13: =IF(R13=FALSE,IF(MOD(ROW(),2)=0,"WHITE","ORANGE")) -> ORANGE | T13: =K13*12 -> 277830 | U13: =U12+T13 -> 1034430 | V13: 5 | W13: =IF(V13>$G$14,0, W12*(1+$G$10)) -> 24310.125 | X13: =IF(W13=0,0,FV((1+$G$16)^(1/12)-1,12,-W13,-X12,1)) -> 1772938.7 | Y13: =W13*12 -> 291721.5
B14: Fresh SIP will continue for (no. of years) | G14: 20 | J14: =IF(J13="","",IF(J13+1>$G$14 + $G$15,"",J13+1)) -> 5 | K14: =IF(J14="","",IF(Q14, IF($G$13="Percentage", IF(OR(ISBLANK($G$12),$G$12=0),K13*(1+$G$10),IF(K13*(1+$G$10)>$G$12,K13,K13*(1+$G$10))), IF(OR(ISBLANK($G$12),$G$12=0),K13+$G$11, IF(K13+$G$11>$G$12,K13, K13+$G$11))), 0)) -> 24310.125 | M14: =IF(J14="","",FV((1+$G$16)^(1/12)-1,12,-K14,IF(ISNUMBER(M13),-M13,0),1)) -> 1772938.7 | Q14: =J14<=$G$14 -> TRUE | R14: =J14="" -> FALSE | S14: =IF(R14=FALSE,IF(MOD(ROW(),2)=0,"WHITE","ORANGE")) -> WHITE | T14: =K14*12 -> 291721.5 | U14: =U13+T14 -> 1326151.5 | V14: 6 | W14: =IF(V14>$G$14,0, W13*(1+$G$10)) -> 25525.631 | X14: =IF(W14=0,0,FV((1+$G$16)^(1/12)-1,12,-W14,-X13,1)) -> 2311564.3 | Y14: =W14*12 -> 306307.58
B15: Thereafter investment will be held for (no. of years) | G15: 10 | J15: =IF(J14="","",IF(J14+1>$G$14 + $G$15,"",J14+1)) -> 6 | K15: =IF(J15="","",IF(Q15, IF($G$13="Percentage", IF(OR(ISBLANK($G$12),$G$12=0),K14*(1+$G$10),IF(K14*(1+$G$10)>$G$12,K14,K14*(1+$G$10))), IF(OR(ISBLANK($G$12),$G$12=0),K14+$G$11, IF(K14+$G$11>$G$12,K14, K14+$G$11))), 0)) -> 25525.631 | M15: =IF(J15="","",FV((1+$G$16)^(1/12)-1,12,-K15,IF(ISNUMBER(M14),-M14,0),1)) -> 2311564.3 | Q15: =J15<=$G$14 -> TRUE | R15: =J15="" -> FALSE | S15: =IF(R15=FALSE,IF(MOD(ROW(),2)=0,"WHITE","ORANGE")) -> ORANGE | T15: =K15*12 -> 306307.58 | U15: =U14+T15 -> 1632459.1 | V15: 7 | W15: =IF(V15>$G$14,0, W14*(1+$G$10)) -> 26801.913 | X15: =IF(W15=0,0,FV((1+$G$16)^(1/12)-1,12,-W15,-X14,1)) -> 2931118.6 | Y15: =W15*12 -> 321622.95
B16: Expected return from SIP (p.a.) | G16: 0.12 | J16: =IF(J15="","",IF(J15+1>$G$14 + $G$15,"",J15+1)) -> 7 | K16: =IF(J16="","",IF(Q16, IF($G$13="Percentage", IF(OR(ISBLANK($G$12),$G$12=0),K15*(1+$G$10),IF(K15*(1+$G$10)>$G$12,K15,K15*(1+$G$10))), IF(OR(ISBLANK($G$12),$G$12=0),K15+$G$11, IF(K15+$G$11>$G$12,K15, K15+$G$11))), 0)) -> 26801.913 | M16: =IF(J16="","",FV((1+$G$16)^(1/12)-1,12,-K16,IF(ISNUMBER(M15),-M15,0),1)) -> 2931118.6 | Q16: =J16<=$G$14 -> TRUE | R16: =J16="" -> FALSE | S16: =IF(R16=FALSE,IF(MOD(ROW(),2)=0,"WHITE","ORANGE")) -> WHITE | T16: =K16*12 -> 321622.95 | U16: =U15+T16 -> 1954082 | V16: 8 | W16: =IF(V16>$G$14,0, W15*(1+$G$10)) -> 28142.008 | X16: =IF(W16=0,0,FV((1+$G$16)^(1/12)-1,12,-W16,-X15,1)) -> 3642127.7 | Y16: =W16*12 -> 337704.1
B17: Lump sum investment amount (if any) | G17: 200000 | J17: =IF(J16="","",IF(J16+1>$G$14 + $G$15,"",J16+1)) -> 8 | K17: =IF(J17="","",IF(Q17, IF($G$13="Percentage", IF(OR(ISBLANK($G$12),$G$12=0),K16*(1+$G$10),IF(K16*(1+$G$10)>$G$12,K16,K16*(1+$G$10))), IF(OR(ISBLANK($G$12),$G$12=0),K16+$G$11, IF(K16+$G$11>$G$12,K16, K16+$G$11))), 0)) -> 28142.008 | M17: =IF(J17="","",FV((1+$G$16)^(1/12)-1,12,-K17,IF(ISNUMBER(M16),-M16,0),1)) -> 3642127.7 | Q17: =J17<=$G$14 -> TRUE | R17: =J17="" -> FALSE | S17: =IF(R17=FALSE,IF(MOD(ROW(),2)=0,"WHITE","ORANGE")) -> ORANGE | T17: =K17*12 -> 337704.1 | U17: =U16+T17 -> 2291786.1 | V17: 9 | W17: =IF(V17>$G$14,0, W16*(1+$G$10)) -> 29549.109 | X17: =IF(W17=0,0,FV((1+$G$16)^(1/12)-1,12,-W17,-X16,1)) -> 4456421.6 | Y17: =W17*12 -> 354589.31
B18: Expected return from lump sum (p.a.) | G18: 0.12 | J18: =IF(J17="","",IF(J17+1>$G$14 + $G$15,"",J17+1)) -> 9 | K18: =IF(J18="","",IF(Q18, IF($G$13="Percentage", IF(OR(ISBLANK($G$12),$G$12=0),K17*(1+$G$10),IF(K17*(1+$G$10)>$G$12,K17,K17*(1+$G$10))), IF(OR(ISBLANK($G$12),$G$12=0),K17+$G$11, IF(K17+$G$11>$G$12,K17, K17+$G$11))), 0)) -> 29549.109 | M18: =IF(J18="","",FV((1+$G$16)^(1/12)-1,12,-K18,IF(ISNUMBER(M17),-M17,0),1)) -> 4456421.6 | Q18: =J18<=$G$14 -> TRUE | R18: =J18="" -> FALSE | S18: =IF(R18=FALSE,IF(MOD(ROW(),2)=0,"WHITE","ORANGE")) -> WHITE | T18: =K18*12 -> 354589.31 | U18: =U17+T18 -> 2646375.4 | V18: 10 | W18: =IF(V18>$G$14,0, W17*(1+$G$10)) -> 31026.564 | X18: =IF(W18=0,0,FV((1+$G$16)^(1/12)-1,12,-W18,-X17,1)) -> 5387292.8 | Y18: =W18*12 -> 372318.77
B19: =IF(G14+G15>50,"Total investment tenure cannot be more than 50 years","") | J19: =IF(J18="","",IF(J18+1>$G$14 + $G$15,"",J18+1)) -> 10 | K19: =IF(J19="","",IF(Q19, IF($G$13="Percentage", IF(OR(ISBLANK($G$12),$G$12=0),K18*(1+$G$10),IF(K18*(1+$G$10)>$G$12,K18,K18*(1+$G$10))), IF(OR(ISBLANK($G$12),$G$12=0),K18+$G$11, IF(K18+$G$11>$G$12,K18, K18+$G$11))), 0)) -> 31026.564 | M19: =IF(J19="","",FV((1+$G$16)^(1/12)-1,12,-K19,IF(ISNUMBER(M18),-M18,0),1)) -> 5387292.8 | Q19: =J19<=$G$14 -> TRUE | R19: =J19="" -> FALSE | S19: =IF(R19=FALSE,IF(MOD(ROW(),2)=0,"WHITE","ORANGE")) -> ORANGE | T19: =K19*12 -> 372318.77 | U19: =U18+T19 -> 3018694.2 | V19: 11 | W19: =IF(V19>$G$14,0, W18*(1+$G$10)) -> 32577.893 | X19: =IF(W19=0,0,FV((1+$G$16)^(1/12)-1,12,-W19,-X18,1)) -> 6449673.5 | Y19: =W19*12 -> 390934.71
D20: TOTAL INVESTMENT | F20: EXPECTED FUTURE VALUE | J20: =IF(J19="","",IF(J19+1>$G$14 + $G$15,"",J19+1)) -> 11 | K20: =IF(J20="","",IF(Q20, IF($G$13="Percentage", IF(OR(ISBLANK($G$12),$G$12=0),K19*(1+$G$10),IF(K19*(1+$G$10)>$G$12,K19,K19*(1+$G$10))), IF(OR(ISBLANK($G$12),$G$12=0),K19+$G$11, IF(K19+$G$11>$G$12,K19, K19+$G$11))), 0)) -> 32577.893 | M20: =IF(J20="","",FV((1+$G$16)^(1/12)-1,12,-K20,IF(ISNUMBER(M19),-M19,0),1)) -> 6449673.5 | Q20: =J20<=$G$14 -> TRUE | R20: =J20="" -> FALSE | S20: =IF(R20=FALSE,IF(MOD(ROW(),2)=0,"WHITE","ORANGE")) -> WHITE | T20: =K20*12 -> 390934.71 | U20: =U19+T20 -> 3409628.9 | V20: 12 | W20: =IF(V20>$G$14,0, W19*(1+$G$10)) -> 34206.787 | X20: =IF(W20=0,0,FV((1+$G$16)^(1/12)-1,12,-W20,-X19,1)) -> 7660335.2 | Y20: =W20*12 -> 410481.45
B21: TOP-UP SIP (A) | D21: =IF(OR(G14+G15>50,AND(OR(ISBLANK(G10),G10=0),OR(ISBLANK(G11),G11=0))),0,VLOOKUP(G14,$J$10:$U$60,12,0)) -> 7935829 | F21: =IF(OR(G14+G15>50,D21=0),0,VLOOKUP(G14+G15,J10:O60,4,0)) -> 79222255 | J21: =IF(J20="","",IF(J20+1>$G$14 + $G$15,"",J20+1)) -> 12 | K21: =IF(J21="","",IF(Q21, IF($G$13="Percentage", IF(OR(ISBLANK($G$12),$G$12=0),K20*(1+$G$10),IF(K20*(1+$G$10)>$G$12,K20,K20*(1+$G$10))), IF(OR(ISBLANK($G$12),$G$12=0),K20+$G$11, IF(K20+$G$11>$G$12,K20, K20+$G$11))), 0)) -> 34206.787 | M21: =IF(J21="","",FV((1+$G$16)^(1/12)-1,12,-K21,IF(ISNUMBER(M20),-M20,0),1)) -> 7660335.2 | Q21: =J21<=$G$14 -> TRUE | R21: =J21="" -> FALSE | S21: =IF(R21=FALSE,IF(MOD(ROW(),2)=0,"WHITE","ORANGE")) -> ORANGE | T21: =K21*12 -> 410481.45 | U21: =U20+T21 -> 3820110.4 | V21: 13 | W21: =IF(V21>$G$14,0, W20*(1+$G$10)) -> 35917.127 | X21: =IF(W21=0,0,FV((1+$G$16)^(1/12)-1,12,-W21,-X20,1)) -> 9038111.4 | Y21: =W21*12 -> 431005.52
B22: FIXED SIP (B) | D22: =G14*12*G9 -> 4800000 | F22: =FV(G16,G15,,-FV((1+G16)^(1/12)-1,G14*12,-G9,,1),1) -> 57138746 | J22: =IF(J21="","",IF(J21+1>$G$14 + $G$15,"",J21+1)) -> 13 | K22: =IF(J22="","",IF(Q22, IF($G$13="Percentage", IF(OR(ISBLANK($G$12),$G$12=0),K21*(1+$G$10),IF(K21*(1+$G$10)>$G$12,K21,K21*(1+$G$10))), IF(OR(ISBLANK($G$12),$G$12=0),K21+$G$11, IF(K21+$G$11>$G$12,K21, K21+$G$11))), 0)) -> 35917.127 | M22: =IF(J22="","",FV((1+$G$16)^(1/12)-1,12,-K22,IF(ISNUMBER(M21),-M21,0),1)) -> 9038111.4 | Q22: =J22<=$G$14 -> TRUE | R22: =J22="" -> FALSE | S22: =IF(R22=FALSE,IF(MOD(ROW(),2)=0,"WHITE","ORANGE")) -> WHITE | T22: =K22*12 -> 431005.52 | U22: =U21+T22 -> 4251115.9 | V22: 14 | W22: =IF(V22>$G$14,0, W21*(1+$G$10)) -> 37712.983 | X22: =IF(W22=0,0,FV((1+$G$16)^(1/12)-1,12,-W22,-X21,1)) -> 10604147 | Y22: =W22*12 -> 452555.79
B23: DIFFERENCE (A - B) | D23: =IF(OR(G14+G15>50,D21=0),0,D21-D22) -> 3135829 | F23: =IF(OR(G14+G15>50,D21=0),0,F21-F22) -> 22083509 | J23: =IF(J22="","",IF(J22+1>$G$14 + $G$15,"",J22+1)) -> 14 | K23: =IF(J23="","",IF(Q23, IF($G$13="Percentage", IF(OR(ISBLANK($G$12),$G$12=0),K22*(1+$G$10),IF(K22*(1+$G$10)>$G$12,K22,K22*(1+$G$10))), IF(OR(ISBLANK($G$12),$G$12=0),K22+$G$11, IF(K22+$G$11>$G$12,K22, K22+$G$11))), 0)) -> 37712.983 | M23: =IF(J23="","",FV((1+$G$16)^(1/12)-1,12,-K23,IF(ISNUMBER(M22),-M22,0),1)) -> 10604147 | Q23: =J23<=$G$14 -> TRUE | R23: =J23="" -> FALSE | S23: =IF(R23=FALSE,IF(MOD(ROW(),2)=0,"WHITE","ORANGE")) -> ORANGE | T23: =K23*12 -> 452555.79 | U23: =U22+T23 -> 4703671.7 | V23: 15 | W23: =IF(V23>$G$14,0, W22*(1+$G$10)) -> 39598.632 | X23: =IF(W23=0,0,FV((1+$G$16)^(1/12)-1,12,-W23,-X22,1)) -> 12382181 | Y23: =W23*12 -> 475183.58
B24: LUMP SUM (C) | D24: =G17 -> 200000 | F24: =FV(G18,G14+G15,,-G17) -> 5991984.4 | J24: =IF(J23="","",IF(J23+1>$G$14 + $G$15,"",J23+1)) -> 15 | K24: =IF(J24="","",IF(Q24, IF($G$13="Percentage", IF(OR(ISBLANK($G$12),$G$12=0),K23*(1+$G$10),IF(K23*(1+$G$10)>$G$12,K23,K23*(1+$G$10))), IF(OR(ISBLANK($G$12),$G$12=0),K23+$G$11, IF(K23+$G$11>$G$12,K23, K23+$G$11))), 0)) -> 39598.632 | M24: =IF(J24="","",FV((1+$G$16)^(1/12)-1,12,-K24,IF(ISNUMBER(M23),-M23,0),1)) -> 12382181 | Q24: =J24<=$G$14 -> TRUE | R24: =J24="" -> FALSE | S24: =IF(R24=FALSE,IF(MOD(ROW(),2)=0,"WHITE","ORANGE")) -> WHITE | T24: =K24*12 -> 475183.58 | U24: =U23+T24 -> 5178855.3 | V24: 16 | W24: =IF(V24>$G$14,0, W23*(1+$G$10)) -> 41578.564 | X24: =IF(W24=0,0,FV((1+$G$16)^(1/12)-1,12,-W24,-X23,1)) -> 14398855 | Y24: =W24*12 -> 498942.76
B25: LUMP SUM + SIP(A) | D25: =D21+D24 -> 8135829 | F25: =F24+F21 -> 85214240 | J25: =IF(J24="","",IF(J24+1>$G$14 + $G$15,"",J24+1)) -> 16 | K25: =IF(J25="","",IF(Q25, IF($G$13="Percentage", IF(OR(ISBLANK($G$12),$G$12=0),K24*(1+$G$10),IF(K24*(1+$G$10)>$G$12,K24,K24*(1+$G$10))), IF(OR(ISBLANK($G$12),$G$12=0),K24+$G$11, IF(K24+$G$11>$G$12,K24, K24+$G$11))), 0)) -> 41578.564 | M25: =IF(J25="","",FV((1+$G$16)^(1/12)-1,12,-K25,IF(ISNUMBER(M24),-M24,0),1)) -> 14398855 | Q25: =J25<=$G$14 -> TRUE | R25: =J25="" -> FALSE | S25: =IF(R25=FALSE,IF(MOD(ROW(),2)=0,"WHITE","ORANGE")) -> ORANGE | T25: =K25*12 -> 498942.76 | U25: =U24+T25 -> 5677798 | V25: 17 | W25: =IF(V25>$G$14,0, W24*(1+$G$10)) -> 43657.492 | X25: =IF(W25=0,0,FV((1+$G$16)^(1/12)-1,12,-W25,-X24,1)) -> 16684071 | Y25: =W25*12 -> 523889.9
B26: LUMP SUM + SIP(B) | D26: =D24+D22 -> 5000000 | F26: =F24+F22 -> 63130731 | J26: =IF(J25="","",IF(J25+1>$G$14 + $G$15,"",J25+1)) -> 17 | K26: =IF(J26="","",IF(Q26, IF($G$13="Percentage", IF(OR(ISBLANK($G$12),$G$12=0),K25*(1+$G$10),IF(K25*(1+$G$10)>$G$12,K25,K25*(1+$G$10))), IF(OR(ISBLANK($G$12),$G$12=0),K25+$G$11, IF(K25+$G$11>$G$12,K25, K25+$G$11))), 0)) -> 43657.492 | M26: =IF(J26="","",FV((1+$G$16)^(1/12)-1,12,-K26,IF(ISNUMBER(M25),-M25,0),1)) -> 16684071 | Q26: =J26<=$G$14 -> TRUE | R26: =J26="" -> FALSE | S26: =IF(R26=FALSE,IF(MOD(ROW(),2)=0,"WHITE","ORANGE")) -> WHITE | T26: =K26*12 -> 523889.9 | U26: =U25+T26 -> 6201687.9 | V26: 18 | W26: =IF(V26>$G$14,0, W25*(1+$G$10)) -> 45840.366 | X26: =IF(W26=0,0,FV((1+$G$16)^(1/12)-1,12,-W26,-X25,1)) -> 19271381 | Y26: =W26*12 -> 550084.4
H27: ="Dated: "& TEXT(TODAY(),"DD-MMM-YYYY") -> Dated: 28-Aug-2025 | J27: =IF(J26="","",IF(J26+1>$G$14 + $G$15,"",J26+1)) -> 18 | K27: =IF(J27="","",IF(Q27, IF($G$13="Percentage", IF(OR(ISBLANK($G$12),$G$12=0),K26*(1+$G$10),IF(K26*(1+$G$10)>$G$12,K26,K26*(1+$G$10))), IF(OR(ISBLANK($G$12),$G$12=0),K26+$G$11, IF(K26+$G$11>$G$12,K26, K26+$G$11))), 0)) -> 45840.366 | M27: =IF(J27="","",FV((1+$G$16)^(1/12)-1,12,-K27,IF(ISNUMBER(M26),-M26,0),1)) -> 19271381 | Q27: =J27<=$G$14 -> TRUE | R27: =J27="" -> FALSE | S27: =IF(R27=FALSE,IF(MOD(ROW(),2)=0,"WHITE","ORANGE")) -> ORANGE | T27: =K27*12 -> 550084.4 | U27: =U26+T27 -> 6751772.3 | V27: 19 | W27: =IF(V27>$G$14,0, W26*(1+$G$10)) -> 48132.385 | X27: =IF(W27=0,0,FV((1+$G$16)^(1/12)-1,12,-W27,-X26,1)) -> 22198428 | Y27: =W27*12 -> 577588.62
B28: Prepared for: | D28: =" "&UPPER('Main Menu'!C29) -> CLIENT NAME | J28: =IF(J27="","",IF(J27+1>$G$14 + $G$15,"",J27+1)) -> 19 | K28: =IF(J28="","",IF(Q28, IF($G$13="Percentage", IF(OR(ISBLANK($G$12),$G$12=0),K27*(1+$G$10),IF(K27*(1+$G$10)>$G$12,K27,K27*(1+$G$10))), IF(OR(ISBLANK($G$12),$G$12=0),K27+$G$11, IF(K27+$G$11>$G$12,K27, K27+$G$11))), 0)) -> 48132.385 | M28: =IF(J28="","",FV((1+$G$16)^(1/12)-1,12,-K28,IF(ISNUMBER(M27),-M27,0),1)) -> 22198428 | Q28: =J28<=$G$14 -> TRUE | R28: =J28="" -> FALSE | S28: =IF(R28=FALSE,IF(MOD(ROW(),2)=0,"WHITE","ORANGE")) -> WHITE | T28: =K28*12 -> 577588.62 | U28: =U27+T28 -> 7329360.9 | V28: 20 | W28: =IF(V28>$G$14,0, W27*(1+$G$10)) -> 50539.004 | X28: =IF(W28=0,0,FV((1+$G$16)^(1/12)-1,12,-W28,-X27,1)) -> 25507446 | Y28: =W28*12 -> 606468.05
B29: Prepared by: | D29: =" "&UPPER('Main Menu'!L29) -> PARTNER NAME | J29: =IF(J28="","",IF(J28+1>$G$14 + $G$15,"",J28+1)) -> 20 | K29: =IF(J29="","",IF(Q29, IF($G$13="Percentage", IF(OR(ISBLANK($G$12),$G$12=0),K28*(1+$G$10),IF(K28*(1+$G$10)>$G$12,K28,K28*(1+$G$10))), IF(OR(ISBLANK($G$12),$G$12=0),K28+$G$11, IF(K28+$G$11>$G$12,K28, K28+$G$11))), 0)) -> 50539.004 | M29: =IF(J29="","",FV((1+$G$16)^(1/12)-1,12,-K29,IF(ISNUMBER(M28),-M28,0),1)) -> 25507446 | Q29: =J29<=$G$14 -> TRUE | R29: =J29="" -> FALSE | S29: =IF(R29=FALSE,IF(MOD(ROW(),2)=0,"WHITE","ORANGE")) -> ORANGE | T29: =K29*12 -> 606468.05 | U29: =U28+T29 -> 7935829 | V29: 21 | W29: =IF(V29>$G$14,0, W28*(1+$G$10)) -> 0 | X29: =IF(W29=0,0,FV((1+$G$16)^(1/12)-1,12,-W29,-X28,1)) -> 0 | Y29: =W29*12 -> 0
J30: =IF(J29="","",IF(J29+1>$G$14 + $G$15,"",J29+1)) -> 21 | K30: =IF(J30="","",IF(Q30, IF($G$13="Percentage", IF(OR(ISBLANK($G$12),$G$12=0),K29*(1+$G$10),IF(K29*(1+$G$10)>$G$12,K29,K29*(1+$G$10))), IF(OR(ISBLANK($G$12),$G$12=0),K29+$G$11, IF(K29+$G$11>$G$12,K29, K29+$G$11))), 0)) -> 0 | M30: =IF(J30="","",FV((1+$G$16)^(1/12)-1,12,-K30,IF(ISNUMBER(M29),-M29,0),1)) -> 28568340 | Q30: =J30<=$G$14 -> FALSE | R30: =J30="" -> FALSE | S30: =IF(R30=FALSE,IF(MOD(ROW(),2)=0,"WHITE","ORANGE")) -> WHITE | T30: =K30*12 -> 0 | U30: =U29+T30 -> 7935829 | V30: 22 | W30: =IF(V30>$G$14,0, W29*(1+$G$10)) -> 0 | X30: =IF(W30=0,0,FV((1+$G$16)^(1/12)-1,12,-W30,-X29,1)) -> 0 | Y30: =W30*12 -> 0
J31: =IF(J30="","",IF(J30+1>$G$14 + $G$15,"",J30+1)) -> 22 | K31: =IF(J31="","",IF(Q31, IF($G$13="Percentage", IF(OR(ISBLANK($G$12),$G$12=0),K30*(1+$G$10),IF(K30*(1+$G$10)>$G$12,K30,K30*(1+$G$10))), IF(OR(ISBLANK($G$12),$G$12=0),K30+$G$11, IF(K30+$G$11>$G$12,K30, K30+$G$11))), 0)) -> 0 | M31: =IF(J31="","",FV((1+$G$16)^(1/12)-1,12,-K31,IF(ISNUMBER(M30),-M30,0),1)) -> 31996540 | Q31: =J31<=$G$14 -> FALSE | R31: =J31="" -> FALSE | S31: =IF(R31=FALSE,IF(MOD(ROW(),2)=0,"WHITE","ORANGE")) -> ORANGE | T31: =K31*12 -> 0 | U31: =U30+T31 -> 7935829 | V31: 23 | W31: =IF(V31>$G$14,0, W30*(1+$G$10)) -> 0 | X31: =IF(W31=0,0,FV((1+$G$16)^(1/12)-1,12,-W31,-X30,1)) -> 0 | Y31: =W31*12 -> 0
J32: =IF(J31="","",IF(J31+1>$G$14 + $G$15,"",J31+1)) -> 23 | K32: =IF(J32="","",IF(Q32, IF($G$13="Percentage", IF(OR(ISBLANK($G$12),$G$12=0),K31*(1+$G$10),IF(K31*(1+$G$10)>$G$12,K31,K31*(1+$G$10))), IF(OR(ISBLANK($G$12),$G$12=0),K31+$G$11, IF(K31+$G$11>$G$12,K31, K31+$G$11))), 0)) -> 0 | M32: =IF(J32="","",FV((1+$G$16)^(1/12)-1,12,-K32,IF(ISNUMBER(M31),-M31,0),1)) -> 35836125 | Q32: =J32<=$G$14 -> FALSE | R32: =J32="" -> FALSE | S32: =IF(R32=FALSE,IF(MOD(ROW(),2)=0,"WHITE","ORANGE")) -> WHITE | T32: =K32*12 -> 0 | U32: =U31+T32 -> 7935829 | V32: 24 | W32: =IF(V32>$G$14,0, W31*(1+$G$10)) -> 0 | X32: =IF(W32=0,0,FV((1+$G$16)^(1/12)-1,12,-W32,-X31,1)) -> 0 | Y32: =W32*12 -> 0
J33: =IF(J32="","",IF(J32+1>$G$14 + $G$15,"",J32+1)) -> 24 | K33: =IF(J33="","",IF(Q33, IF($G$13="Percentage", IF(OR(ISBLANK($G$12),$G$12=0),K32*(1+$G$10),IF(K32*(1+$G$10)>$G$12,K32,K32*(1+$G$10))), IF(OR(ISBLANK($G$12),$G$12=0),K32+$G$11, IF(K32+$G$11>$G$12,K32, K32+$G$11))), 0)) -> 0 | M33: =IF(J33="","",FV((1+$G$16)^(1/12)-1,12,-K33,IF(ISNUMBER(M32),-M32,0),1)) -> 40136460 | Q33: =J33<=$G$14 -> FALSE | R33: =J33="" -> FALSE | S33: =IF(R33=FALSE,IF(MOD(ROW(),2)=0,"WHITE","ORANGE")) -> ORANGE | T33: =K33*12 -> 0 | U33: =U32+T33 -> 7935829 | V33: 25 | W33: =IF(V33>$G$14,0, W32*(1+$G$10)) -> 0 | X33: =IF(W33=0,0,FV((1+$G$16)^(1/12)-1,12,-W33,-X32,1)) -> 0 | Y33: =W33*12 -> 0
J34: =IF(J33="","",IF(J33+1>$G$14 + $G$15,"",J33+1)) -> 25 | K34: =IF(J34="","",IF(Q34, IF($G$13="Percentage", IF(OR(ISBLANK($G$12),$G$12=0),K33*(1+$G$10),IF(K33*(1+$G$10)>$G$12,K33,K33*(1+$G$10))), IF(OR(ISBLANK($G$12),$G$12=0),K33+$G$11, IF(K33+$G$11>$G$12,K33, K33+$G$11))), 0)) -> 0 | M34: =IF(J34="","",FV((1+$G$16)^(1/12)-1,12,-K34,IF(ISNUMBER(M33),-M33,0),1)) -> 44952835 | Q34: =J34<=$G$14 -> FALSE | R34: =J34="" -> FALSE | S34: =IF(R34=FALSE,IF(MOD(ROW(),2)=0,"WHITE","ORANGE")) -> WHITE | T34: =K34*12 -> 0 | U34: =U33+T34 -> 7935829 | V34: 26 | W34: =IF(V34>$G$14,0, W33*(1+$G$10)) -> 0 | X34: =IF(W34=0,0,FV((1+$G$16)^(1/12)-1,12,-W34,-X33,1)) -> 0 | Y34: =W34*12 -> 0
J35: =IF(J34="","",IF(J34+1>$G$14 + $G$15,"",J34+1)) -> 26 | K35: =IF(J35="","",IF(Q35, IF($G$13="Percentage", IF(OR(ISBLANK($G$12),$G$12=0),K34*(1+$G$10),IF(K34*(1+$G$10)>$G$12,K34,K34*(1+$G$10))), IF(OR(ISBLANK($G$12),$G$12=0),K34+$G$11, IF(K34+$G$11>$G$12,K34, K34+$G$11))), 0)) -> 0 | M35: =IF(J35="","",FV((1+$G$16)^(1/12)-1,12,-K35,IF(ISNUMBER(M34),-M34,0),1)) -> 50347176 | Q35: =J35<=$G$14 -> FALSE | R35: =J35="" -> FALSE | S35: =IF(R35=FALSE,IF(MOD(ROW(),2)=0,"WHITE","ORANGE")) -> ORANGE | T35: =K35*12 -> 0 | U35: =U34+T35 -> 7935829 | V35: 27 | W35: =IF(V35>$G$14,0, W34*(1+$G$10)) -> 0 | X35: =IF(W35=0,0,FV((1+$G$16)^(1/12)-1,12,-W35,-X34,1)) -> 0 | Y35: =W35*12 -> 0
J36: =IF(J35="","",IF(J35+1>$G$14 + $G$15,"",J35+1)) -> 27 | K36: =IF(J36="","",IF(Q36, IF($G$13="Percentage", IF(OR(ISBLANK($G$12),$G$12=0),K35*(1+$G$10),IF(K35*(1+$G$10)>$G$12,K35,K35*(1+$G$10))), IF(OR(ISBLANK($G$12),$G$12=0),K35+$G$11, IF(K35+$G$11>$G$12,K35, K35+$G$11))), 0)) -> 0 | M36: =IF(J36="","",FV((1+$G$16)^(1/12)-1,12,-K36,IF(ISNUMBER(M35),-M35,0),1)) -> 56388837 | Q36: =J36<=$G$14 -> FALSE | R36: =J36="" -> FALSE | S36: =IF(R36=FALSE,IF(MOD(ROW(),2)=0,"WHITE","ORANGE")) -> WHITE | T36: =K36*12 -> 0 | U36: =U35+T36 -> 7935829 | V36: 28 | W36: =IF(V36>$G$14,0, W35*(1+$G$10)) -> 0 | X36: =IF(W36=0,0,FV((1+$G$16)^(1/12)-1,12,-W36,-X35,1)) -> 0 | Y36: =W36*12 -> 0
J37: =IF(J36="","",IF(J36+1>$G$14 + $G$15,"",J36+1)) -> 28 | K37: =IF(J37="","",IF(Q37, IF($G$13="Percentage", IF(OR(ISBLANK($G$12),$G$12=0),K36*(1+$G$10),IF(K36*(1+$G$10)>$G$12,K36,K36*(1+$G$10))), IF(OR(ISBLANK($G$12),$G$12=0),K36+$G$11, IF(K36+$G$11>$G$12,K36, K36+$G$11))), 0)) -> 0 | M37: =IF(J37="","",FV((1+$G$16)^(1/12)-1,12,-K37,IF(ISNUMBER(M36),-M36,0),1)) -> 63155497 | Q37: =J37<=$G$14 -> FALSE | R37: =J37="" -> FALSE | S37: =IF(R37=FALSE,IF(MOD(ROW(),2)=0,"WHITE","ORANGE")) -> ORANGE | T37: =K37*12 -> 0 | U37: =U36+T37 -> 7935829 | V37: 29 | W37: =IF(V37>$G$14,0, W36*(1+$G$10)) -> 0 | X37: =IF(W37=0,0,FV((1+$G$16)^(1/12)-1,12,-W37,-X36,1)) -> 0 | Y37: =W37*12 -> 0
J38: =IF(J37="","",IF(J37+1>$G$14 + $G$15,"",J37+1)) -> 29 | K38: =IF(J38="","",IF(Q38, IF($G$13="Percentage", IF(OR(ISBLANK($G$12),$G$12=0),K37*(1+$G$10),IF(K37*(1+$G$10)>$G$12,K37,K37*(1+$G$10))), IF(OR(ISBLANK($G$12),$G$12=0),K37+$G$11, IF(K37+$G$11>$G$12,K37, K37+$G$11))), 0)) -> 0 | M38: =IF(J38="","",FV((1+$G$16)^(1/12)-1,12,-K38,IF(ISNUMBER(M37),-M37,0),1)) -> 70734157 | Q38: =J38<=$G$14 -> FALSE | R38: =J38="" -> FALSE | S38: =IF(R38=FALSE,IF(MOD(ROW(),2)=0,"WHITE","ORANGE")) -> WHITE | T38: =K38*12 -> 0 | U38: =U37+T38 -> 7935829 | V38: 30 | W38: =IF(V38>$G$14,0, W37*(1+$G$10)) -> 0 | X38: =IF(W38=0,0,FV((1+$G$16)^(1/12)-1,12,-W38,-X37,1)) -> 0 | Y38: =W38*12 -> 0
J39: =IF(J38="","",IF(J38+1>$G$14 + $G$15,"",J38+1)) -> 30 | K39: =IF(J39="","",IF(Q39, IF($G$13="Percentage", IF(OR(ISBLANK($G$12),$G$12=0),K38*(1+$G$10),IF(K38*(1+$G$10)>$G$12,K38,K38*(1+$G$10))), IF(OR(ISBLANK($G$12),$G$12=0),K38+$G$11, IF(K38+$G$11>$G$12,K38, K38+$G$11))), 0)) -> 0 | M39: =IF(J39="","",FV((1+$G$16)^(1/12)-1,12,-K39,IF(ISNUMBER(M38),-M38,0),1)) -> 79222255 | Q39: =J39<=$G$14 -> FALSE | R39: =J39="" -> FALSE | S39: =IF(R39=FALSE,IF(MOD(ROW(),2)=0,"WHITE","ORANGE")) -> ORANGE | T39: =K39*12 -> 0 | U39: =U38+T39 -> 7935829 | V39: 31 | W39: =IF(V39>$G$14,0, W38*(1+$G$10)) -> 0 | X39: =IF(W39=0,0,FV((1+$G$16)^(1/12)-1,12,-W39,-X38,1)) -> 0 | Y39: =W39*12 -> 0
J40: =IF(J39="","",IF(J39+1>$G$14 + $G$15,"",J39+1)) | K40: =IF(J40="","",IF(Q40, IF($G$13="Percentage", IF(OR(ISBLANK($G$12),$G$12=0),K39*(1+$G$10),IF(K39*(1+$G$10)>$G$12,K39,K39*(1+$G$10))), IF(OR(ISBLANK($G$12),$G$12=0),K39+$G$11, IF(K39+$G$11>$G$12,K39, K39+$G$11))), 0)) | M40: =IF(J40="","",FV((1+$G$16)^(1/12)-1,12,-K40,IF(ISNUMBER(M39),-M39,0),1)) | Q40: =J40<=$G$14 -> FALSE | R40: =J40="" -> TRUE | S40: =IF(R40=FALSE,IF(MOD(ROW(),2)=0,"WHITE","ORANGE")) -> FALSE | T40: =K40*12 -> #VALUE! | U40: =U39+T40 -> #VALUE! | V40: 32 | W40: =IF(V40>$G$14,0, W39*(1+$G$10)) -> 0 | X40: =IF(W40=0,0,FV((1+$G$16)^(1/12)-1,12,-W40,-X39,1)) -> 0 | Y40: =W40*12 -> 0
J41: =IF(J40="","",IF(J40+1>$G$14 + $G$15,"",J40+1)) | K41: =IF(J41="","",IF(Q41, IF($G$13="Percentage", IF(OR(ISBLANK($G$12),$G$12=0),K40*(1+$G$10),IF(K40*(1+$G$10)>$G$12,K40,K40*(1+$G$10))), IF(OR(ISBLANK($G$12),$G$12=0),K40+$G$11, IF(K40+$G$11>$G$12,K40, K40+$G$11))), 0)) | M41: =IF(J41="","",FV((1+$G$16)^(1/12)-1,12,-K41,IF(ISNUMBER(M40),-M40,0),1)) | Q41: =J41<=$G$14 -> FALSE | R41: =J41="" -> TRUE | S41: =IF(R41=FALSE,IF(MOD(ROW(),2)=0,"WHITE","ORANGE")) -> FALSE | T41: =K41*12 -> #VALUE! | U41: =U40+T41 -> #VALUE! | V41: 33 | W41: =IF(V41>$G$14,0, W40*(1+$G$10)) -> 0 | X41: =IF(W41=0,0,FV((1+$G$16)^(1/12)-1,12,-W41,-X40,1)) -> 0 | Y41: =W41*12 -> 0
...

Sheet 1 (2)
A2: BACK | B2: SIP & LUMP SUM - ALL IN ONE
D5: Future Wealth Creation | J5: Required Investment to Make
B7: How much investment is required?
T8: YEARS | U8: SIP INVESTMENT | V8: WEALTH
B9: Goal is due after (no. of years) | G9: 20 | J9: YEAR | K9: MTHLY SIP AMT | M9: WEALTH @ END OF YEAR | T9: 1 | U9: 100 | V9: =FV((1+$G$12)^(1/12)-1,12,-U9,,1) -> 1276.6498
B10: Cost of goal as of today | G10: 1000000 | J10: 1 | K10: =G20 -> 3811.4822 | M10: =FV((1+$G$12)^(1/12)-1,12,-K10,IF(ISNUMBER(M9),-M9,0),1) -> 48659.279 | Q10: =J10<=$G$19 -> TRUE | R10: =J10="" -> FALSE | S10: =IF(R10=FALSE,IF(MOD(ROW(),2)=0,"WHITE","ORANGE")) -> WHITE | T10: 2 | U10: =U9*(1+$G$18) -> 110 | V10: =FV((1+$G$12)^(1/12)-1,12,-U10,-V9,1) -> 2834.1625
B11: Assumed inflation for the goal | G11: 0.07 | J11: =IF(J10="","",IF(J10+1>$G$9,"",J10+1)) -> 2 | K11: =IF(J11="","",IF(Q11,K10*(1+$G$18),0)) -> 4192.6304 | M11: =IF(J11="","",FV((1+$G$12)^(1/12)-1,12,-K11,IF(ISNUMBER(M10),-M10,0),1)) -> 108023.6 | Q11: =J11<=$G$19 -> TRUE | R11: =J11="" -> FALSE | S11: =IF(R11=FALSE,IF(MOD(ROW(),2)=0,"WHITE","ORANGE")) -> ORANGE | T11: 3 | U11: =U10*(1+$G$18) -> 121 | V11: =FV((1+$G$12)^(1/12)-1,12,-U11,-V10,1) -> 4719.0083
B12: Expected return from new investment | G12: 0.12 | J12: =IF(J11="","",IF(J11+1>$G$9,"",J11+1)) -> 3 | K12: =IF(J12="","",IF(Q12,K11*(1+$G$18),0)) -> 4611.8934 | M12: =IF(J12="","",FV((1+$G$12)^(1/12)-1,12,-K12,IF(ISNUMBER(M11),-M11,0),1)) -> 179864.16 | Q12: =J12<=$G$19 -> TRUE | R12: =J12="" -> FALSE | S12: =IF(R12=FALSE,IF(MOD(ROW(),2)=0,"WHITE","ORANGE")) -> WHITE | T12: 4 | U12: =U11*(1+$G$18) -> 133.1 | V12: =FV((1+$G$12)^(1/12)-1,12,-U12,-V11,1) -> 6984.5102
B13: Value of assets linked to this goal | G13: 0 | J13: =IF(J12="","",IF(J12+1>$G$9,"",J12+1)) -> 4 | K13: =IF(J13="","",IF(Q13,K12*(1+$G$18),0)) -> 5073.0828 | M13: =IF(J13="","",FV((1+$G$12)^(1/12)-1,12,-K13,IF(ISNUMBER(M12),-M12,0),1)) -> 266213.36 | Q13: =J13<=$G$19 -> TRUE | R13: =J13="" -> FALSE | S13: =IF(R13=FALSE,IF(MOD(ROW(),2)=0,"WHITE","ORANGE")) -> ORANGE | T13: 5 | U13: =U12*(1+$G$18) -> 146.41 | V13: =FV((1+$G$12)^(1/12)-1,12,-U13,-V12,1) -> 9691.7943
B14: Assumed return from linked assets | G14: 0.1 | J14: =IF(J13="","",IF(J13+1>$G$9,"",J13+1)) -> 5 | K14: =IF(J14="","",IF(Q14,K13*(1+$G$18),0)) -> 5580.3911 | M14: =IF(J14="","",FV((1+$G$12)^(1/12)-1,12,-K14,IF(ISNUMBER(M13),-M13,0),1)) -> 369401.01 | Q14: =J14<=$G$19 -> TRUE | R14: =J14="" -> FALSE | S14: =IF(R14=FALSE,IF(MOD(ROW(),2)=0,"WHITE","ORANGE")) -> WHITE | T14: 6 | U14: =U13*(1+$G$18) -> 161.051 | V14: =FV((1+$G$12)^(1/12)-1,12,-U14,-V13,1) -> 12910.867
B15: FUTURE VALUE OF THE GOAL | G15: =FV(G11,G9,,-G10) -> 3869684.5 | J15: =IF(J14="","",IF(J14+1>$G$9,"",J14+1)) -> 6 | K15: =IF(J15="","",IF(Q15,K14*(1+$G$18),0)) -> 6138.4302 | M15: =IF(J15="","",FV((1+$G$12)^(1/12)-1,12,-K15,IF(ISNUMBER(M14),-M14,0),1)) -> 492095.39 | Q15: =J15<=$G$19 -> TRUE | R15: =J15="" -> FALSE | S15: =IF(R15=FALSE,IF(MOD(ROW(),2)=0,"WHITE","ORANGE")) -> ORANGE | T15: 7 | U15: =U14*(1+$G$18) -> 177.1561 | V15: =FV((1+$G$12)^(1/12)-1,12,-U15,-V14,1) -> 16721.834
J16: =IF(J15="","",IF(J15+1>$G$9,"",J15+1)) -> 7 | K16: =IF(J16="","",IF(Q16,K15*(1+$G$18),0)) -> 6752.2732 | M16: =IF(J16="","",FV((1+$G$12)^(1/12)-1,12,-K16,IF(ISNUMBER(M15),-M15,0),1)) -> 637349.72 | Q16: =J16<=$G$19 -> TRUE | R16: =J16="" -> FALSE | S16: =IF(R16=FALSE,IF(MOD(ROW(),2)=0,"WHITE","ORANGE")) -> WHITE | T16: 8 | U16: =U15*(1+$G$18) -> 194.87171 | V16: =FV((1+$G$12)^(1/12)-1,12,-U16,-V15,1) -> 21216.283
B17: REQUIRED LUMP SUM INVESTMENT | G17: =-PV(G12,G9,,G15-FV(G14,G9,,-G13),) -> 401157.67 | J17: =IF(J16="","",IF(J16+1>$G$9,"",J16+1)) -> 8 | K17: =IF(J17="","",IF(Q17,K16*(1+$G$18),0)) -> 7427.5005 | M17: =IF(J17="","",FV((1+$G$12)^(1/12)-1,12,-K17,IF(ISNUMBER(M16),-M16,0),1)) -> 808654.86 | Q17: =J17<=$G$19 -> TRUE | R17: =J17="" -> FALSE | S17: =IF(R17=FALSE,IF(MOD(ROW(),2)=0,"WHITE","ORANGE")) -> ORANGE | T17: 9 | U17: =U16*(1+$G$18) -> 214.35888 | V17: =FV((1+$G$12)^(1/12)-1,12,-U17,-V16,1) -> 26498.849
B18: SIP top-up % (after every 12 months) | G18: 0.1 | J18: =IF(J17="","",IF(J17+1>$G$9,"",J17+1)) -> 9 | K18: =IF(J18="","",IF(Q18,K17*(1+$G$18),0)) -> 8170.2505 | M18: =IF(J18="","",FV((1+$G$12)^(1/12)-1,12,-K18,IF(ISNUMBER(M17),-M17,0),1)) -> 1009998.9 | Q18: =J18<=$G$19 -> TRUE | R18: =J18="" -> FALSE | S18: =IF(R18=FALSE,IF(MOD(ROW(),2)=0,"WHITE","ORANGE")) -> WHITE | T18: 10 | U18: =U17*(1+$G$18) -> 235.79477 | V18: =FV((1+$G$12)^(1/12)-1,12,-U18,-V17,1) -> 32688.985
B19: Fresh SIP investment will continue for | G19: 10 | J19: =IF(J18="","",IF(J18+1>$G$9,"",J18+1)) -> 10 | K19: =IF(J19="","",IF(Q19,K18*(1+$G$18),0)) -> 8987.2756 | M19: =IF(J19="","",FV((1+$G$12)^(1/12)-1,12,-K19,IF(ISNUMBER(M18),-M18,0),1)) -> 1245934.8 | Q19: =J19<=$G$19 -> TRUE | R19: =J19="" -> FALSE | S19: =IF(R19=FALSE,IF(MOD(ROW(),2)=0,"WHITE","ORANGE")) -> ORANGE | T19: 11 | U19: =U18*(1+$G$18) -> 259.37425 | V19: =FV((1+$G$12)^(1/12)-1,12,-U19,-V18,1) -> 39922.964
B20: REQUIRED SIP INVESTMENT | G20: =IF(G19>G9, 0, IF(OR(ISBLANK(G19),G19=0),(100/VLOOKUP(G9,T9:V58,3,0))*(G15-FV(G14,G9,,-G13)), (100/VLOOKUP(G19,T9:V58,3,0))*-PV(G12,G9-G19,,(G15-FV(G14,G9,,-G13)),))) -> 3811.4822 | J20: =IF(J19="","",IF(J19+1>$G$9,"",J19+1)) -> 11 | K20: =IF(J20="","",IF(Q20,K19*(1+$G$18),0)) -> 0 | M20: =IF(J20="","",FV((1+$G$12)^(1/12)-1,12,-K20,IF(ISNUMBER(M19),-M19,0),1)) -> 1395447 | Q20: =J20<=$G$19 -> FALSE | R20: =J20="" -> FALSE | S20: =IF(R20=FALSE,IF(MOD(ROW(),2)=0,"WHITE","ORANGE")) -> WHITE | T20: 12 | U20: =U19*(1+$G$18) -> 285.31167 | V20: =FV((1+$G$12)^(1/12)-1,12,-U20,-V19,1) -> 48356.15
B21: =IF(G19>G9,"SIP tenure cannot be more than the goal tenure","") | J21: =IF(J20="","",IF(J20+1>$G$9,"",J20+1)) -> 12 | K21: =IF(J21="","",IF(Q21,K20*(1+$G$18),0)) -> 0 | M21: =IF(J21="","",FV((1+$G$12)^(1/12)-1,12,-K21,IF(ISNUMBER(M20),-M20,0),1)) -> 1562900.7 | Q21: =J21<=$G$19 -> FALSE | R21: =J21="" -> FALSE | S21: =IF(R21=FALSE,IF(MOD(ROW(),2)=0,"WHITE","ORANGE")) -> ORANGE | T21: 13 | U21: =U20*(1+$G$18) -> 313.84284 | V21: =FV((1+$G$12)^(1/12)-1,12,-U21,-V20,1) -> 58165.562
J22: =IF(J21="","",IF(J21+1>$G$9,"",J21+1)) -> 13 | K22: =IF(J22="","",IF(Q22,K21*(1+$G$18),0)) -> 0 | M22: =IF(J22="","",FV((1+$G$12)^(1/12)-1,12,-K22,IF(ISNUMBER(M21),-M21,0),1)) -> 1750448.7 | Q22: =J22<=$G$19 -> FALSE | R22: =J22="" -> FALSE | S22: =IF(R22=FALSE,IF(MOD(ROW(),2)=0,"WHITE","ORANGE")) -> WHITE | T22: 14 | U22: =U21*(1+$G$18) -> 345.22712 | V22: =FV((1+$G$12)^(1/12)-1,12,-U22,-V21,1) -> 69552.771
B23: Prepared for: | D23: =" "&UPPER('Main Menu'!C29) -> CLIENT NAME | J23: =IF(J22="","",IF(J22+1>$G$9,"",J22+1)) -> 14 | K23: =IF(J23="","",IF(Q23,K22*(1+$G$18),0)) -> 0 | M23: =IF(J23="","",FV((1+$G$12)^(1/12)-1,12,-K23,IF(ISNUMBER(M22),-M22,0),1)) -> 1960502.6 | Q23: =J23<=$G$19 -> FALSE | R23: =J23="" -> FALSE | S23: =IF(R23=FALSE,IF(MOD(ROW(),2)=0,"WHITE","ORANGE")) -> ORANGE | T23: 15 | U23: =U22*(1+$G$18) -> 379.74983 | V23: =FV((1+$G$12)^(1/12)-1,12,-U23,-V22,1) -> 82747.179
B24: Prepared by: | D24: =" "&UPPER('Main Menu'!L29) -> PARTNER NAME | J24: =IF(J23="","",IF(J23+1>$G$9,"",J23+1)) -> 15 | K24: =IF(J24="","",IF(Q24,K23*(1+$G$18),0)) -> 0 | M24: =IF(J24="","",FV((1+$G$12)^(1/12)-1,12,-K24,IF(ISNUMBER(M23),-M23,0),1)) -> 2195762.9 | Q24: =J24<=$G$19 -> FALSE | R24: =J24="" -> FALSE | S24: =IF(R24=FALSE,IF(MOD(ROW(),2)=0,"WHITE","ORANGE")) -> WHITE | T24: 16 | U24: =U23*(1+$G$18) -> 417.72482 | V24: =FV((1+$G$12)^(1/12)-1,12,-U24,-V23,1) -> 98009.723
G25: ="Dated: "& TEXT(TODAY(),"DD-MMM-YYYY") -> Dated: 28-Aug-2025 | J25: =IF(J24="","",IF(J24+1>$G$9,"",J24+1)) -> 16 | K25: =IF(J25="","",IF(Q25,K24*(1+$G$18),0)) -> 0 | M25: =IF(J25="","",FV((1+$G$12)^(1/12)-1,12,-K25,IF(ISNUMBER(M24),-M24,0),1)) -> 2459254.4 | Q25: =J25<=$G$19 -> FALSE | R25: =J25="" -> FALSE | S25: =IF(R25=FALSE,IF(MOD(ROW(),2)=0,"WHITE","ORANGE")) -> ORANGE | T25: 17 | U25: =U24*(1+$G$18) -> 459.4973 | V25: =FV((1+$G$12)^(1/12)-1,12,-U25,-V24,1) -> 115637.06
J26: =IF(J25="","",IF(J25+1>$G$9,"",J25+1)) -> 17 | K26: =IF(J26="","",IF(Q26,K25*(1+$G$18),0)) -> 0 | M26: =IF(J26="","",FV((1+$G$12)^(1/12)-1,12,-K26,IF(ISNUMBER(M25),-M25,0),1)) -> 2754365 | Q26: =J26<=$G$19 -> FALSE | R26: =J26="" -> FALSE | S26: =IF(R26=FALSE,IF(MOD(ROW(),2)=0,"WHITE","ORANGE")) -> WHITE | T26: 18 | U26: =U25*(1+$G$18) -> 505.44703 | V26: =FV((1+$G$12)^(1/12)-1,12,-U26,-V25,1) -> 135966.3
J27: =IF(J26="","",IF(J26+1>$G$9,"",J26+1)) -> 18 | K27: =IF(J27="","",IF(Q27,K26*(1+$G$18),0)) -> 0 | M27: =IF(J27="","",FV((1+$G$12)^(1/12)-1,12,-K27,IF(ISNUMBER(M26),-M26,0),1)) -> 3084888.8 | Q27: =J27<=$G$19 -> FALSE | R27: =J27="" -> FALSE | S27: =IF(R27=FALSE,IF(MOD(ROW(),2)=0,"WHITE","ORANGE")) -> ORANGE | T27: 19 | U27: =U26*(1+$G$18) -> 555.99173 | V27: =FV((1+$G$12)^(1/12)-1,12,-U27,-V26,1) -> 159380.32
J28: =IF(J27="","",IF(J27+1>$G$9,"",J27+1)) -> 19 | K28: =IF(J28="","",IF(Q28,K27*(1+$G$18),0)) -> 0 | M28: =IF(J28="","",FV((1+$G$12)^(1/12)-1,12,-K28,IF(ISNUMBER(M27),-M27,0),1)) -> 3455075.4 | Q28: =J28<=$G$19 -> FALSE | R28: =J28="" -> FALSE | S28: =IF(R28=FALSE,IF(MOD(ROW(),2)=0,"WHITE","ORANGE")) -> WHITE | T28: 20 | U28: =U27*(1+$G$18) -> 611.5909 | V28: =FV((1+$G$12)^(1/12)-1,12,-U28,-V27,1) -> 186313.83
J29: =IF(J28="","",IF(J28+1>$G$9,"",J28+1)) -> 20 | K29: =IF(J29="","",IF(Q29,K28*(1+$G$18),0)) -> 0 | M29: =IF(J29="","",FV((1+$G$12)^(1/12)-1,12,-K29,IF(ISNUMBER(M28),-M28,0),1)) -> 3869684.5 | Q29: =J29<=$G$19 -> FALSE | R29: =J29="" -> FALSE | S29: =IF(R29=FALSE,IF(MOD(ROW(),2)=0,"WHITE","ORANGE")) -> ORANGE | T29: 21 | U29: =U28*(1+$G$18) -> 672.74999 | V29: =FV((1+$G$12)^(1/12)-1,12,-U29,-V28,1) -> 217260.15
J30: =IF(J29="","",IF(J29+1>$G$9,"",J29+1)) | K30: =IF(J30="","",IF(Q30,K29*(1+$G$18),0)) | M30: =IF(J30="","",FV((1+$G$12)^(1/12)-1,12,-K30,IF(ISNUMBER(M29),-M29,0),1)) | Q30: =J30<=$G$19 -> FALSE | R30: =J30="" -> TRUE | S30: =IF(R30=FALSE,IF(MOD(ROW(),2)=0,"WHITE","ORANGE")) -> FALSE | T30: 22 | U30: =U29*(1+$G$18) -> 740.02499 | V30: =FV((1+$G$12)^(1/12)-1,12,-U30,-V29,1) -> 252778.9
J31: =IF(J30="","",IF(J30+1>$G$9,"",J30+1)) | K31: =IF(J31="","",IF(Q31,K30*(1+$G$18),0)) | M31: =IF(J31="","",FV((1+$G$12)^(1/12)-1,12,-K31,IF(ISNUMBER(M30),-M30,0),1)) | Q31: =J31<=$G$19 -> FALSE | R31: =J31="" -> TRUE | S31: =IF(R31=FALSE,IF(MOD(ROW(),2)=0,"WHITE","ORANGE")) -> FALSE | T31: 23 | U31: =U30*(1+$G$18) -> 814.02749 | V31: =FV((1+$G$12)^(1/12)-1,12,-U31,-V30,1) -> 293504.65
J32: =IF(J31="","",IF(J31+1>$G$9,"",J31+1)) | K32: =IF(J32="","",IF(Q32,K31*(1+$G$18),0)) | M32: =IF(J32="","",FV((1+$G$12)^(1/12)-1,12,-K32,IF(ISNUMBER(M31),-M31,0),1)) | Q32: =J32<=$G$19 -> FALSE | R32: =J32="" -> TRUE | S32: =IF(R32=FALSE,IF(MOD(ROW(),2)=0,"WHITE","ORANGE")) -> FALSE | T32: 24 | U32: =U31*(1+$G$18) -> 895.43024 | V32: =FV((1+$G$12)^(1/12)-1,12,-U32,-V31,1) -> 340156.71
J33: =IF(J32="","",IF(J32+1>$G$9,"",J32+1)) | K33: =IF(J33="","",IF(Q33,K32*(1+$G$18),0)) | M33: =IF(J33="","",FV((1+$G$12)^(1/12)-1,12,-K33,IF(ISNUMBER(M32),-M32,0),1)) | Q33: =J33<=$G$19 -> FALSE | R33: =J33="" -> TRUE | S33: =IF(R33=FALSE,IF(MOD(ROW(),2)=0,"WHITE","ORANGE")) -> FALSE | T33: 25 | U33: =U32*(1+$G$18) -> 984.97327 | V33: =FV((1+$G$12)^(1/12)-1,12,-U33,-V32,1) -> 393550.18
J34: =IF(J33="","",IF(J33+1>$G$9,"",J33+1)) | K34: =IF(J34="","",IF(Q34,K33*(1+$G$18),0)) | M34: =IF(J34="","",FV((1+$G$12)^(1/12)-1,12,-K34,IF(ISNUMBER(M33),-M33,0),1)) | Q34: =J34<=$G$19 -> FALSE | R34: =J34="" -> TRUE | S34: =IF(R34=FALSE,IF(MOD(ROW(),2)=0,"WHITE","ORANGE")) -> FALSE | T34: 26 | U34: =U33*(1+$G$18) -> 1083.4706 | V34: =FV((1+$G$12)^(1/12)-1,12,-U34,-V33,1) -> 454608.33
J35: =IF(J34="","",IF(J34+1>$G$9,"",J34+1)) | K35: =IF(J35="","",IF(Q35,K34*(1+$G$18),0)) | M35: =IF(J35="","",FV((1+$G$12)^(1/12)-1,12,-K35,IF(ISNUMBER(M34),-M34,0),1)) | Q35: =J35<=$G$19 -> FALSE | R35: =J35="" -> TRUE | S35: =IF(R35=FALSE,IF(MOD(ROW(),2)=0,"WHITE","ORANGE")) -> FALSE | T35: 27 | U35: =U34*(1+$G$18) -> 1191.8177 | V35: =FV((1+$G$12)^(1/12)-1,12,-U35,-V34,1) -> 524376.66
J36: =IF(J35="","",IF(J35+1>$G$9,"",J35+1)) | K36: =IF(J36="","",IF(Q36,K35*(1+$G$18),0)) | M36: =IF(J36="","",FV((1+$G$12)^(1/12)-1,12,-K36,IF(ISNUMBER(M35),-M35,0),1)) | Q36: =J36<=$G$19 -> FALSE | R36: =J36="" -> TRUE | S36: =IF(R36=FALSE,IF(MOD(ROW(),2)=0,"WHITE","ORANGE")) -> FALSE | T36: 28 | U36: =U35*(1+$G$18) -> 1310.9994 | V36: =FV((1+$G$12)^(1/12)-1,12,-U36,-V35,1) -> 604038.73
J37: =IF(J36="","",IF(J36+1>$G$9,"",J36+1)) | K37: =IF(J37="","",IF(Q37,K36*(1+$G$18),0)) | M37: =IF(J37="","",FV((1+$G$12)^(1/12)-1,12,-K37,IF(ISNUMBER(M36),-M36,0),1)) | Q37: =J37<=$G$19 -> FALSE | R37: =J37="" -> TRUE | S37: =IF(R37=FALSE,IF(MOD(ROW(),2)=0,"WHITE","ORANGE")) -> FALSE | T37: 29 | U37: =U36*(1+$G$18) -> 1442.0994 | V37: =FV((1+$G$12)^(1/12)-1,12,-U37,-V36,1) -> 694933.94
... J58: =IF(J57="","",IF(J57+1>$G$9,"",J57+1)) | K58: =IF(J58="","",IF(Q58,K57*(1+$G$18),0)) | M58: =IF(J58="","",FV((1+$G$12)^(1/12)-1,12,-K58,IF(ISNUMBER(M57),-M57,0),1)) | Q58: =J58<=$G$19 -> FALSE | R58: =J58="" -> TRUE | S58: =IF(R58=FALSE,IF(MOD(ROW(),2)=0,"WHITE","ORANGE")) -> FALSE | T58: 50 | U58: =U57*(1+$G$18) -> 10671.896 | V58: =FV((1+$G$12)^(1/12)-1,12,-U58,-V57,1) -> 10954379
J59: =IF(J58="","",IF(J58+1>$G$9,"",J58+1)) | K59: =IF(J59="","",IF(Q59,K58*(1+$G$18),0)) | M59: =IF(J59="","",FV((1+$G$12)^(1/12)-1,12,-K59,IF(ISNUMBER(M58),-M58,0),1)) | Q59: =J59<=$G$19 -> FALSE | R59: =J59="" -> TRUE | S59: =IF(R59=FALSE,IF(MOD(ROW(),2)=0,"WHITE","ORANGE")) -> FALSE
J60: =IF(J59="","",IF(J59+1>$G$9,"",J59+1)) | K60: =IF(J60="","",IF(Q60,K59*(1+$G$18),0)) | M60: =IF(J60="","",FV((1+$G$12)^(1/12)-1,12,-K60,IF(ISNUMBER(M59),-M59,0),1)) | Q60: =J60<=$G$19 -> FALSE | R60: =J60="" -> TRUE | S60: =IF(R60=FALSE,IF(MOD(ROW(),2)=0,"WHITE","ORANGE")) -> FALSE

Sheet 2
A2: BACK | B2: SWP REGULAR INCOME GENERATION
I4: ASSET ALLOCATION FOR WITHDRAWAL PHASE:
B5: Current corpus | F5: 30000000 | I5: PORTFOLIO ALLOCATION | L5: AMOUNT | N5: EXP. RETURN
B6: Current monthly requirement | F6: 150000 | I6: Liquidity | K6: 0.1 | L6: =$F$5*K6 -> 3000000 | N6: 0.06
B7: Assumed inflation | F7: 0.06 | I7: Safety | K7: 0.3 | L7: =$F$5*K7 -> 9000000 | N7: 0.08
B8: Current age | F8: 45 | I8: Growth | K8: 0.6 | L8: =$F$5*K8 -> 18000000 | N8: 0.15
B9: Withdrawal start age | F9: 50 | I9: Portfolio weighted average return | N9: =SUMPRODUCT(L6:L8,N6:N8)/SUM(L6:L8) -> 0.12
B10: Assumed return till withdrawal starts | F10: 0.08 | I10: Portfolio would continue till the age of | N10: {=IFERROR(INDEX(B17:B66,MATCH(1,Q17:Q66,0)-2),">"&B17+49)} -> >99
B12: Prepared for: | D12: =" "&UPPER('Main Menu'!C29) -> CLIENT NAME
B13: Prepared by: | D13: =" "&UPPER('Main Menu'!L29) -> PARTNER NAME | I13: ="Dated: "& TEXT(TODAY(),"DD-MMM-YYYY") -> Dated: 28-Aug-2025
B14: The chart on the right hand side shows the end-of-year corpus for first 25 years à
B15: AGE | C15: START OF THE YEAR CORPUS | E15: WITHDRAWAL | I15: END OF THE YEAR CORPUS
E16: YEARLY | G16: MONTHLY
B17: =F9 -> 50 | C17: =IF(F9>F8,FV(F10,F9-F8,,-F5),F5) -> 44079842 | E17: =IF(F9>F8,FV(F7,F9-F8,,-F6)*12,12*F6) -> 2408806 | G17: =E17/12 -> 200733.84 | I17: =FV($N$9,1,,-(C17-E17)) -> 46671561 | P17: =B17="" -> FALSE | Q17: =P17*1 -> 0 | T17: =IF(ISBLANK(I17),0,IF(I17>=$F$5,0,1)) -> 0
B18: =IF(OR(I17<=0,B17=""),"",B17+1) -> 51 | C18: =IF(I17<=0,"",I17) -> 46671561 | E18: =IF(C18="","",E17*(1+$F$7)) -> 2553334.4 | G18: =IF(E18="","",E18/12) -> 212777.87 | I18: =IF(G18="","",FV($N$9,1,,-(C18-E18))) -> 49412413 | P18: =B18="" -> FALSE | Q18: =P18*1 -> 0 | T18: =IF(ISBLANK(I18),0,IF(I18>=$F$5,0,1)) -> 0
B19: =IF(OR(I18<=0,B18=""),"",B18+1) -> 52 | C19: =IF(I18<=0,"",I18) -> 49412413 | E19: =IF(C19="","",E18*(1+$F$7)) -> 2706534.5 | G19: =IF(E19="","",E19/12) -> 225544.54 | I19: =IF(G19="","",FV($N$9,1,,-(C19-E19))) -> 52310584 | P19: =B19="" -> FALSE | Q19: =P19*1 -> 0 | T19: =IF(ISBLANK(I19),0,IF(I19>=$F$5,0,1)) -> 0
B20: =IF(OR(I19<=0,B19=""),"",B19+1) -> 53 | C20: =IF(I19<=0,"",I19) -> 52310584 | E20: =IF(C20="","",E19*(1+$F$7)) -> 2868926.5 | G20: =IF(E20="","",E20/12) -> 239077.21 | I20: =IF(G20="","",FV($N$9,1,,-(C20-E20))) -> 55374657 | P20: =B20="" -> FALSE | Q20: =P20*1 -> 0 | T20: =IF(ISBLANK(I20),0,IF(I20>=$F$5,0,1)) -> 0
B21: =IF(OR(I20<=0,B20=""),"",B20+1) -> 54 | C21: =IF(I20<=0,"",I20) -> 55374657 | E21: =IF(C21="","",E20*(1+$F$7)) -> 3041062.1 | G21: =IF(E21="","",E21/12) -> 253421.84 | I21: =IF(G21="","",FV($N$9,1,,-(C21-E21))) -> 58613626 | P21: =B21="" -> FALSE | Q21: =P21*1 -> 0 | T21: =IF(ISBLANK(I21),0,IF(I21>=$F$5,0,1)) -> 0
B22: =IF(OR(I21<=0,B21=""),"",B21+1) -> 55 | C22: =IF(I21<=0,"",I21) -> 58613626 | E22: =IF(C22="","",E21*(1+$F$7)) -> 3223525.9 | G22: =IF(E22="","",E22/12) -> 268627.15 | I22: =IF(G22="","",FV($N$9,1,,-(C22-E22))) -> 62036912 | P22: =B22="" -> FALSE | Q22: =P22*1 -> 0 | T22: =IF(ISBLANK(I22),0,IF(I22>=$F$5,0,1)) -> 0
B23: =IF(OR(I22<=0,B22=""),"",B22+1) -> 56 | C23: =IF(I22<=0,"",I22) -> 62036912 | E23: =IF(C23="","",E22*(1+$F$7)) -> 3416937.4 | G23: =IF(E23="","",E23/12) -> 284744.78 | I23: =IF(G23="","",FV($N$9,1,,-(C23-E23))) -> 65654372 | P23: =B23="" -> FALSE | Q23: =P23*1 -> 0 | T23: =IF(ISBLANK(I23),0,IF(I23>=$F$5,0,1)) -> 0
B24: =IF(OR(I23<=0,B23=""),"",B23+1) -> 57 | C24: =IF(I23<=0,"",I23) -> 65654372 | E24: =IF(C24="","",E23*(1+$F$7)) -> 3621953.6 | G24: =IF(E24="","",E24/12) -> 301829.47 | I24: =IF(G24="","",FV($N$9,1,,-(C24-E24))) -> 69476308 | P24: =B24="" -> FALSE | Q24: =P24*1 -> 0 | T24: =IF(ISBLANK(I24),0,IF(I24>=$F$5,0,1)) -> 0
B25: =IF(OR(I24<=0,B24=""),"",B24+1) -> 58 | C25: =IF(I24<=0,"",I24) -> 69476308 | E25: =IF(C25="","",E24*(1+$F$7)) -> 3839270.9 | G25: =IF(E25="","",E25/12) -> 319939.24 | I25: =IF(G25="","",FV($N$9,1,,-(C25-E25))) -> 73513482 | P25: =B25="" -> FALSE | Q25: =P25*1 -> 0 | T25: =IF(ISBLANK(I25),0,IF(I25>=$F$5,0,1)) -> 0
B26: =IF(OR(I25<=0,B25=""),"",B25+1) -> 59 | C26: =IF(I25<=0,"",I25) -> 73513482 | E26: =IF(C26="","",E25*(1+$F$7)) -> 4069627.1 | G26: =IF(E26="","",E26/12) -> 339135.59 | I26: =IF(G26="","",FV($N$9,1,,-(C26-E26))) -> 77777117 | P26: =B26="" -> FALSE | Q26: =P26*1 -> 0 | T26: =IF(ISBLANK(I26),0,IF(I26>=$F$5,0,1)) -> 0
B27: =IF(OR(I26<=0,B26=""),"",B26+1) -> 60 | C27: =IF(I26<=0,"",I26) -> 77777117 | E27: =IF(C27="","",E26*(1+$F$7)) -> 4313804.7 | G27: =IF(E27="","",E27/12) -> 359483.73 | I27: =IF(G27="","",FV($N$9,1,,-(C27-E27))) -> 82278910 | P27: =B27="" -> FALSE | Q27: =P27*1 -> 0 | T27: =IF(ISBLANK(I27),0,IF(I27>=$F$5,0,1)) -> 0
B28: =IF(OR(I27<=0,B27=""),"",B27+1) -> 61 | C28: =IF(I27<=0,"",I27) -> 82278910 | E28: =IF(C28="","",E27*(1+$F$7)) -> 4572633 | G28: =IF(E28="","",E28/12) -> 381052.75 | I28: =IF(G28="","",FV($N$9,1,,-(C28-E28))) -> 87031030 | P28: =B28="" -> FALSE | Q28: =P28*1 -> 0 | T28: =IF(ISBLANK(I28),0,IF(I28>=$F$5,0,1)) -> 0
B29: =IF(OR(I28<=0,B28=""),"",B28+1) -> 62 | C29: =IF(I28<=0,"",I28) -> 87031030 | E29: =IF(C29="","",E28*(1+$F$7)) -> 4846991 | G29: =IF(E29="","",E29/12) -> 403915.92 | I29: =IF(G29="","",FV($N$9,1,,-(C29-E29))) -> 92046124 | P29: =B29="" -> FALSE | Q29: =P29*1 -> 0 | T29: =IF(ISBLANK(I29),0,IF(I29>=$F$5,0,1)) -> 0
... B66: =IF(OR(I65<=0,B65=""),"",B65+1) -> 99 | C66: =IF(I65<=0,"",I65) -> 5.5312479e+08 | E66: =IF(C66="","",E65*(1+$F$7)) -> 41859037 | G66: =IF(E66="","",E66/12) -> 3488253.1 | I66: =IF(G66="","",FV($N$9,1,,-(C66-E66))) -> 5.7261765e+08 | P66: =B66="" -> FALSE | Q66: =P66*1 -> 0 | T66: =IF(ISBLANK(I66),0,IF(I66>=$F$5,0,1)) -> 0

Sheet 3
R1: 0
A2: BACK | B2: SWP VS INTEREST PAYOUT | R2: 0.052
R3: 0.104 | T3: 8.43
R4: 0.156 | T4: 8.43
B5: Investment amount | H5: 10000000 | J5: Mutual Fund type | N5: Equity | R5: 0.208 | S5: Equity | T5: =SUM(T3:T4) -> 16.86
B6: Assumed MF return | H6: 0.08 | R6: 0.26 | S6: Debt
B7: Assumed FD return | H7: 0.08 | J7: Withdrawal % from MF | N7: Similar to FD | R7: 0.312 | S7: Other
B8: Tax slab | H8: 0.312 | J8: Withdrawal % from Mutual Fund | N8: 0.1
B9: Mutual Fund Types: Equity (equity exposure >= 65%), Other (equity exposure >35% and <65%) and Debt (equity exposure <= 35%)
B10: Prepared for: | D10: =" "&UPPER('Main Menu'!C29) -> CLIENT NAME | I10: Prepared by: | K10: =" "&UPPER('Main Menu'!L29) -> PARTNER NAME | M10: r
N11: ="Dated: "& TEXT(TODAY(),"DD-MMM-YYYY") -> Dated: 28-Aug-2025
B12: Comparison is to be done for how many years? | H12: 10 | K12: ="i.e."&H12&" financial years including purchase and sale year" -> i.e.10 financial years including purchase and sale year | R12: Assumed inflation | V12: 0.07
B14: MUTUAL FUND SWP TAXATION (YEARLY) | J14: FIXED DEPOSIT INTEREST TAXATION (YEARLY) | R14: =SUM(R18:S22) -> 3860418.1 | T14: =SUM(T17:U21) -> 3088406.5
B15: YEAR | C15: WITHDRAWAL FROM MF | E15: TAX TYPE | F15: TOTAL TAX PAID | H15: EFFECTIVE TAX RATE | J15: WITHDRAWAL FROM FD | L15: TOTAL TAX PAID | N15: EFFECTIVE TAX RATE | R15: FD WITHDRAWAL | T15: MF WITHDRAWAL | U15: MF WITHDRAWAL% | X15: =IF(N7="Diff. than FD",N8,H7) -> 0.08
U16: Amount Withdrawn (MF) | X16: =$H$5*((1+$X$15)^(1/12)-1) -> 64340.301
B17: TOTAL | C17: =SUM(C18:D42) -> 7720836.1 | F17: =SUM(F18:F42) -> 296089.65 | H17: =F17/C17 -> 0.038349428 | J17: =SUM(J18:K42) -> 7720836.1 | L17: =SUM(L18:M42) -> 2408900.9 | N17: =L17/J17 -> 0.312
B18: 1 | C18: =IF(B18="","",T18) -> 772083.61 | E18: =IF(B18="","",IF(AND($N$5="Equity", B18=1), "STCG", IF($N$5="Debt", "NA", IF(AND($N$5="Other", B18<3), "STCG", "LTCG")))) -> STCG | F18: =IF(B18="","",SUMIFS($G$49:$G$348,$Y$49:$Y$348,"="&B18)) -> 5911.1284 | H18: =IF(B18="","",IF(T18=0,"",F18/T18)) -> 0.0076560728 | J18: =IF(B18="","",R18) -> 772083.61 | L18: =IF(B18="","",R18*$H$8) -> 240890.09 | N18: =IF(B18="","",L18/R18) -> 0.312 | R18: =12*$J$49 -> 772083.61 | T18: =SUMIFS($T$49:$T$108,$B$49:$B$108,"<="&12) -> 772083.61 | U18: 0
B19: =IF(B18="","",IF(B18+1<=$H$12,B18+1,"")) -> 2 | C19: =IF(B19="","",T19) -> 772083.61 | E19: =IF(B19="","",IF(AND($N$5="Equity", B19=1), "STCG", IF($N$5="Debt", "NA", IF(AND($N$5="Other", B19<3), "STCG", "LTCG")))) -> LTCG | F19: =IF(B19="","",SUMIFS($G$49:$G$348,$Y$49:$Y$348,"="&B19)) -> 10776.57 | H19: =IF(B19="","",IF(T19=0,"",F19/T19)) -> 0.013957775 | J19: =IF(B19="","",R19) -> 772083.61 | L19: =IF(B19="","",R19*$H$8) -> 240890.09 | N19: =IF(B19="","",L19/R19) -> 0.312 | R19: =12*$J$49 -> 772083.61 | T19: =SUMIFS($T$49:$T$348,$B$49:$B$348,">"&U19, $B$49:$B$348, "<="&(U19+12)) -> 772083.61 | U19: 12
B20: =IF(B19="","",IF(B19+1<=$H$12,B19+1,"")) -> 3 | C20: =IF(B20="","",T20) -> 772083.61 | E20: =IF(B20="","",IF(AND($N$5="Equity", B20=1), "STCG", IF($N$5="Debt", "NA", IF(AND($N$5="Other", B20<3), "STCG", "LTCG")))) -> LTCG | F20: =IF(B20="","",SUMIFS($G$49:$G$348,$Y$49:$Y$348,"="&B20)) -> 17127.228 | H20: =IF(B20="","",IF(T20=0,"",F20/T20)) -> 0.022183125 | J20: =IF(B20="","",R20) -> 772083.61 | L20: =IF(B20="","",R20*$H$8) -> 240890.09 | N20: =IF(B20="","",L20/R20) -> 0.312 | R20: =12*$J$49 -> 772083.61 | T20: =SUMIFS($T$49:$T$348,$B$49:$B$348,">"&U20, $B$49:$B$348, "<="&(U20+12)) -> 772083.61 | U20: 24
B21: =IF(B20="","",IF(B20+1<=$H$12,B20+1,"")) -> 4 | C21: =IF(B21="","",T21) -> 772083.61 | E21: =IF(B21="","",IF(AND($N$5="Equity", B21=1), "STCG", IF($N$5="Debt", "NA", IF(AND($N$5="Other", B21<3), "STCG", "LTCG")))) -> LTCG | F21: =IF(B21="","",SUMIFS($G$49:$G$348,$Y$49:$Y$348,"="&B21)) -> 23007.466 | H21: =IF(B21="","",IF(T21=0,"",F21/T21)) -> 0.02979919 | J21: =IF(B21="","",R21) -> 772083.61 | L21: =IF(B21="","",R21*$H$8) -> 240890.09 | N21: =IF(B21="","",L21/R21) -> 0.312 | R21: =12*$J$49 -> 772083.61 | T21: =SUMIFS($T$49:$T$348,$B$49:$B$348,">"&U21, $B$49:$B$348, "<="&(U21+12)) -> 772083.61 | U21: 36
B22: =IF(B21="","",IF(B21+1<=$H$12,B21+1,"")) -> 5 | C22: =IF(B22="","",T22) -> 772083.61 | E22: =IF(B22="","",IF(AND($N$5="Equity", B22=1), "STCG", IF($N$5="Debt", "NA", IF(AND($N$5="Other", B22<3), "STCG", "LTCG")))) -> LTCG | F22: =IF(B22="","",SUMIFS($G$49:$G$348,$Y$49:$Y$348,"="&B22)) -> 28452.132 | H22: =IF(B22="","",IF(T22=0,"",F22/T22)) -> 0.036851102 | J22: =IF(B22="","",R22) -> 772083.61 | L22: =IF(B22="","",R22*$H$8) -> 240890.09 | N22: =IF(B22="","",L22/R22) -> 0.312 | R22: =12*$J$49 -> 772083.61 | T22: =SUMIFS($T$49:$T$348,$B$49:$B$348,">"&U22, $B$49:$B$348, "<="&(U22+12)) -> 772083.61 | U22: 48
B23: =IF(B22="","",IF(B22+1<=$H$12,B22+1,"")) -> 6 | C23: =IF(B23="","",T23) -> 772083.61 | E23: =IF(B23="","",IF(AND($N$5="Equity", B23=1), "STCG", IF($N$5="Debt", "NA", IF(AND($N$5="Other", B23<3), "STCG", "LTCG")))) -> LTCG | F23: =IF(B23="","",SUMIFS($G$49:$G$348,$Y$49:$Y$348,"="&B23)) -> 33493.489 | H23: =IF(B23="","",IF(T23=0,"",F23/T23)) -> 0.04338065 | J23: =IF(B23="","",R23) -> 772083.61 | L23: =IF(B23="","",R23*$H$8) -> 240890.09 | N23: =IF(B23="","",L23/R23) -> 0.312 | R23: =12*$J$49 -> 772083.61 | T23: =SUMIFS($T$49:$T$348,$B$49:$B$348,">"&U23, $B$49:$B$348, "<="&(U23+12)) -> 772083.61 | U23: 60
B24: =IF(B23="","",IF(B23+1<=$H$12,B23+1,"")) -> 7 | C24: =IF(B24="","",T24) -> 772083.61 | E24: =IF(B24="","",IF(AND($N$5="Equity", B24=1), "STCG", IF($N$5="Debt", "NA", IF(AND($N$5="Other", B24<3), "STCG", "LTCG")))) -> LTCG | F24: =IF(B24="","",SUMIFS($G$49:$G$348,$Y$49:$Y$348,"="&B24)) -> 38161.412 | H24: =IF(B24="","",IF(T24=0,"",F24/T24)) -> 0.049426528 | J24: =IF(B24="","",R24) -> 772083.61 | L24: =IF(B24="","",R24*$H$8) -> 240890.09 | N24: =IF(B24="","",L24/R24) -> 0.312 | R24: =12*$J$49 -> 772083.61 | T24: =SUMIFS($T$49:$T$348,$B$49:$B$348,">"&U24, $B$49:$B$348, "<="&(U24+12)) -> 772083.61 | U24: 72
B25: =IF(B24="","",IF(B24+1<=$H$12,B24+1,"")) -> 8 | C25: =IF(B25="","",T25) -> 772083.61 | E25: =IF(B25="","",IF(AND($N$5="Equity", B25=1), "STCG", IF($N$5="Debt", "NA", IF(AND($N$5="Other", B25<3), "STCG", "LTCG")))) -> LTCG | F25: =IF(B25="","",SUMIFS($G$49:$G$348,$Y$49:$Y$348,"="&B25)) -> 42483.563 | H25: =IF(B25="","",IF(T25=0,"",F25/T25)) -> 0.055024563 | J25: =IF(B25="","",R25) -> 772083.61 | L25: =IF(B25="","",R25*$H$8) -> 240890.09 | N25: =IF(B25="","",L25/R25) -> 0.312 | R25: =12*$J$49 -> 772083.61 | T25: =SUMIFS($T$49:$T$348,$B$49:$B$348,">"&U25, $B$49:$B$348, "<="&(U25+12)) -> 772083.61 | U25: 84
B26: =IF(B25="","",IF(B25+1<=$H$12,B25+1,"")) -> 9 | C26: =IF(B26="","",T26) -> 772083.61 | E26: =IF(B26="","",IF(AND($N$5="Equity", B26=1), "STCG", IF($N$5="Debt", "NA", IF(AND($N$5="Other", B26<3), "STCG", "LTCG")))) -> LTCG | F26: =IF(B26="","",SUMIFS($G$49:$G$348,$Y$49:$Y$348,"="&B26)) -> 46485.555 | H26: =IF(B26="","",IF(T26=0,"",F26/T26)) -> 0.060207928 | J26: =IF(B26="","",R26) -> 772083.61 | L26: =IF(B26="","",R26*$H$8) -> 240890.09 | N26: =IF(B26="","",L26/R26) -> 0.312 | R26: =12*$J$49 -> 772083.61 | T26: =SUMIFS($T$49:$T$348,$B$49:$B$348,">"&U26, $B$49:$B$348, "<="&(U26+12)) -> 772083.61 | U26: 96
B27: =IF(B26="","",IF(B26+1<=$H$12,B26+1,"")) -> 10 | C27: =IF(B27="","",T27) -> 772083.61 | E27: =IF(B27="","",IF(AND($N$5="Equity", B27=1), "STCG", IF($N$5="Debt", "NA", IF(AND($N$5="Other", B27<3), "STCG", "LTCG")))) -> LTCG | F27: =IF(B27="","",SUMIFS($G$49:$G$348,$Y$49:$Y$348,"="&B27)) -> 50191.103 | H27: =IF(B27="","",IF(T27=0,"",F27/T27)) -> 0.065007341 | J27: =IF(B27="","",R27) -> 772083.61 | L27: =IF(B27="","",R27*$H$8) -> 240890.09 | N27: =IF(B27="","",L27/R27) -> 0.312 | R27: =12*$J$49 -> 772083.61 | T27: =SUMIFS($T$49:$T$348,$B$49:$B$348,">"&U27, $B$49:$B$348, "<="&(U27+12)) -> 772083.61 | U27: 108
B28: =IF(B27="","",IF(B27+1<=$H$12,B27+1,"")) | C28: =IF(B28="","",T28) | E28: =IF(B28="","",IF(AND($N$5="Equity", B28=1), "STCG", IF($N$5="Debt", "NA", IF(AND($N$5="Other", B28<3), "STCG", "LTCG")))) | F28: =IF(B28="","",SUMIFS($G$49:$G$348,$Y$49:$Y$348,"="&B28)) | H28: =IF(B28="","",IF(T28=0,"",F28/T28)) | J28: =IF(B28="","",R28) | L28: =IF(B28="","",R28*$H$8) | N28: =IF(B28="","",L28/R28) | R28: =12*$J$49 -> 772083.61 | T28: =SUMIFS($T$49:$T$348,$B$49:$B$348,">"&U28, $B$49:$B$348, "<="&(U28+12)) -> 772083.61 | U28: 120
B29: =IF(B28="","",IF(B28+1<=$H$12,B28+1,"")) | C29: =IF(B29="","",T29) | E29: =IF(B29="","",IF(AND($N$5="Equity", B29=1), "STCG", IF($N$5="Debt", "NA", IF(AND($N$5="Other", B29<3), "STCG", "LTCG")))) | F29: =IF(B29="","",SUMIFS($G$49:$G$348,$Y$49:$Y$348,"="&B29)) | H29: =IF(B29="","",IF(T29=0,"",F29/T29)) | J29: =IF(B29="","",R29) | L29: =IF(B29="","",R29*$H$8) | N29: =IF(B29="","",L29/R29) | R29: =12*$J$49 -> 772083.61 | T29: =SUMIFS($T$49:$T$348,$B$49:$B$348,">"&U29, $B$49:$B$348, "<="&(U29+12)) -> 772083.61 | U29: 132
B30: =IF(B29="","",IF(B29+1<=$H$12,B29+1,"")) | C30: =IF(B30="","",T30) | E30: =IF(B30="","",IF(AND($N$5="Equity", B30=1), "STCG", IF($N$5="Debt", "NA", IF(AND($N$5="Other", B30<3), "STCG", "LTCG")))) | F30: =IF(B30="","",SUMIFS($G$49:$G$348,$Y$49:$Y$348,"="&B30)) | H30: =IF(B30="","",IF(T30=0,"",F30/T30)) | J30: =IF(B30="","",R30) | L30: =IF(B30="","",R30*$H$8) | N30: =IF(B30="","",L30/R30) | R30: =12*$J$49 -> 772083.61 | T30: =SUMIFS($T$49:$T$348,$B$49:$B$348,">"&U30, $B$49:$B$348, "<="&(U30+12)) -> 772083.61 | U30: 144
... B42: =IF(B41="","",IF(B41+1<=$H$12,B41+1,"")) | C42: =IF(B42="","",T42) | E42: =IF(B42="","",IF(AND($N$5="Equity", B42=1), "STCG", IF($N$5="Debt", "NA", IF(AND($N$5="Other", B42<3), "STCG", "LTCG")))) | F42: =IF(B42="","",SUMIFS($G$49:$G$348,$Y$49:$Y$348,"="&B42)) | H42: =IF(B42="","",IF(T42=0,"",F42/T42)) | J42: =IF(B42="","",R42) | L42: =IF(B42="","",R42*$H$8) | N42: =IF(B42="","",L42/R42) | R42: =12*$J$49 -> 772083.61 | T42: =SUMIFS($T$49:$T$348,$B$49:$B$348,">"&U42, $B$49:$B$348, "<="&(U42+12)) -> 772083.61 | U42: 288
B43: ="Fund value at the end of "&$H$12&" years:" -> Fund value at the end of 10 years: | H43: =VLOOKUP($H$12*12,$B$49:$I$348,7,0) -> 10000000 | K43: ="FD value after "&$H$12&" years:" -> FD value after 10 years: | N43: =N348 -> 10000000
B44: *Please note that exemption of Long Term Capital Gain of upto Rs. 1 Lakh for Equity Fund's long-term taxation has not been considered in case of monthly withdrawals
R45: Capital Gain (Non-Equity) | T45: =INDEX($S$49:$S$348,MATCH($H$12*12,$X$49:$X$348,0))*(INDEX($D$49:$D$348,MATCH($H$12*12,$X$49:$X$348,0))-FV(V12,$H$12-1,,-10)) -> 1484376.6 | V45: Capital Gain (Specified) | X45: =INDEX($S$49:$S$348,MATCH($H$12*12,$X$49:$X$348,0))*(INDEX($D$49:$D$348,MATCH($H$12*12,$X$49:$X$348,0))-10) -> 5368065.1 | Z45: Capital Gain (Equity) | AB45: =INDEX($S$49:$S$348,MATCH($H$12*12,$X$49:$X$348,0))*(INDEX($D$49:$D$348,MATCH($H$12*12,$X$49:$X$348,0))-10) -> 5368065.1
B46: MUTUAL FUND SWP TAXATION (MONTHLY) | J46: FIXED DEPOSIT INTEREST TAXATION (MONTHLY)
B47: MONTH | C47: SWP AMT | D47: NAV | E47: STCG | F47: LTCG* | G47: TAX PAID | H47: FUND VALUE | J47: INTEREST PAYOUT | L47: TAX PAID | N47: FD VALUE | R47: UNITS REDEEMED | S47: BALANCE UNITS | T47: Amt Withdrawn
S48: =H5/10 -> 1000000
B49: 1 | C49: =T49 -> 64340.301 | D49: =10*(1+(1+$H$6)^(1/12)-1) -> 10.06434 | E49: =IF(AND(OR($N$5="Other",$N$5="Debt"), B49<24),R49*(D49-10), IF(AND($N$5="Equity", B49<12),R49*(D49-10), 0)) -> 411.32098 | F49: =IF(AND(OR($N$5="Other",$N$5="Debt"), B49>=24),R49*(D49-10), IF(AND($N$5="Equity", B49>=12),R49*(D49-10),0)) -> 0 | G49: =IF(AND($N$5="Equity", B49< 12), E49*20%, IF(AND($N$5="Equity", B49>= 12),F49*12.5%, IF(AND($N$5="Other", B49<24),E49*$H$8, IF(AND($N$5="Other", B49>=24),F49*12.5%,F49*$H$8)))) -> 82.264197 | H49: =S49*D49 -> 10000000 | J49: =$H$5*((1+$H$7)^(1/12)-1) -> 64340.301 | L49: =J49*$H$8 -> 20074.174 | N49: =$H$5 -> 10000000 | P49: =ROUNDUP(B49/12,0) - 1 -> 0 | R49: =IF($X$16/D49>S48,S48,$X$16/D49) -> 6392.898 | S49: =S48-R49 -> 993607.1 | T49: =IF($X$16/D49>S48,S48*D49,$X$16) -> 64340.301 | X49: 1 | Y49: 1
B50: 2 | C50: =T50 -> 64340.301 | D50: =D49*(1+(1+$H$6)^(1/12)-1) -> 10.129095 | E50: =IF(AND(OR($N$5="Other",$N$5="Debt"), B50<24),R50*(D50-10), IF(AND($N$5="Equity", B50<12),R50*(D50-10), 0)) -> 820.01243 | F50: =IF(AND(OR($N$5="Other",$N$5="Debt"), B50>=24),R50*(D50-10), IF(AND($N$5="Equity", B50>=12),R50*(D50-10),0)) -> 0 | G50: =IF(AND($N$5="Equity", B50< 12), E50*20%, IF(AND($N$5="Equity", B50>= 12),F50*12.5%, IF(AND($N$5="Other", B50<24),E50*$H$8, IF(AND($N$5="Other", B50>=24),F50*12.5%,F50*$H$8)))) -> 164.00249 | H50: =S50*D50 -> 10000000 | J50: =$H$5*((1+$H$7)^(1/12)-1) -> 64340.301 | L50: =J50*$H$8 -> 20074.174 | N50: =$H$5 -> 10000000 | P50: =ROUNDUP(B50/12,0) - 1 -> 0 | R50: =IF($X$16/D50>S49,S49,$X$16/D50) -> 6352.0289 | S50: =S49-R50 -> 987255.07 | T50: =IF($X$16/D50>S49,S49*D50,$X$16) -> 64340.301 | X50: 2 | Y50: 1
B51: 3 | C51: =T51 -> 64340.301 | D51: =D50*(1+(1+$H$6)^(1/12)-1) -> 10.194265 | E51: =IF(AND(OR($N$5="Other",$N$5="Debt"), B51<24),R51*(D51-10), IF(AND($N$5="Equity", B51<12),R51*(D51-10), 0)) -> 1226.0912 | F51: =IF(AND(OR($N$5="Other",$N$5="Debt"), B51>=24),R51*(D51-10), IF(AND($N$5="Equity", B51>=12),R51*(D51-10),0)) -> 0 | G51: =IF(AND($N$5="Equity", B51< 12), E51*20%, IF(AND($N$5="Equity", B51>= 12),F51*12.5%, IF(AND($N$5="Other", B51<24),E51*$H$8, IF(AND($N$5="Other", B51>=24),F51*12.5%,F51*$H$8)))) -> 245.21823 | H51: =S51*D51 -> 10000000 | J51: =$H$5*((1+$H$7)^(1/12)-1) -> 64340.301 | L51: =J51*$H$8 -> 20074.174 | N51: =$H$5 -> 10000000 | P51: =ROUNDUP(B51/12,0) - 1 -> 0 | R51: =IF($X$16/D51>S50,S50,$X$16/D51) -> 6311.421 | S51: =S50-R51 -> 980943.65 | T51: =IF($X$16/D51>S50,S50*D51,$X$16) -> 64340.301 | X51: 3 | Y51: 1
